[INFO     2014-09-01 12:26:13,668 bulkloader.py] Logging to bulkloader-log-20140901.122613
[INFO     2014-09-01 12:26:13,668 bulkloader.py] Throttling transfers:
[INFO     2014-09-01 12:26:13,668 bulkloader.py] Bandwidth: 250000 bytes/second
[INFO     2014-09-01 12:26:13,668 bulkloader.py] HTTP connections: 8/second
[INFO     2014-09-01 12:26:13,669 bulkloader.py] Entities inserted/fetched/modified: 20/second
[INFO     2014-09-01 12:26:13,669 bulkloader.py] Batch Size: 10
[INFO     2014-09-01 12:26:13,670 bulkloader.py] Opening database: bulkloader-progress-20140901.122613.sql3
[DEBUG    2014-09-01 12:26:13,674 bulkloader.py] [Thread-1] RestoreThread: started
[DEBUG    2014-09-01 12:26:19,284 bulkloader.py] [Thread-2] RestoreThread: started
[DEBUG    2014-09-01 12:26:19,285 bulkloader.py] Configuring remote_api. url_path = /_ah/remote_api, servername = 127.0.0.1:8000
[DEBUG    2014-09-01 12:26:19,285 bulkloader.py] [Thread-1] RestoreThread: exiting
[DEBUG    2014-09-01 12:26:19,285 adaptive_thread_pool.py] [WorkerThread-0] WorkerThread: started
[DEBUG    2014-09-01 12:26:19,293 bulkloader.py] Bulkloader using app_id: dev~tpbgui
[INFO     2014-09-01 12:26:19,293 bulkloader.py] Connecting to 127.0.0.1:8000/_ah/remote_api
[ERROR    2014-09-01 12:26:38,685 bulkloader.py] Exception during authentication
Traceback (most recent call last):
  File "/Users/jaco/google-cloud-sdk/platform/google_appengine/google/appengine/tools/bulkloader.py", line 3466, in Run
    self.request_manager.Authenticate()
  File "/Users/jaco/google-cloud-sdk/platform/google_appengine/google/appengine/tools/bulkloader.py", line 1329, in Authenticate
    remote_api_stub.MaybeInvokeAuthentication()
  File "/Users/jaco/google-cloud-sdk/platform/google_appengine/google/appengine/ext/remote_api/remote_api_stub.py", line 740, in MaybeInvokeAuthentication
    datastore_stub._server.Send(datastore_stub._path, payload=None)
  File "/Users/jaco/google-cloud-sdk/platform/google_appengine/google/appengine/tools/appengine_rpc.py", line 419, in Send
    self._Authenticate()
  File "/Users/jaco/google-cloud-sdk/platform/google_appengine/google/appengine/tools/appengine_rpc.py", line 560, in _Authenticate
    super(HttpRpcServer, self)._Authenticate()
  File "/Users/jaco/google-cloud-sdk/platform/google_appengine/google/appengine/tools/appengine_rpc.py", line 356, in _Authenticate
    self._GetAuthCookie(auth_token)
  File "/Users/jaco/google-cloud-sdk/platform/google_appengine/google/appengine/tools/appengine_rpc.py", line 289, in _GetAuthCookie
    response.headers, response.fp)
HTTPError: HTTP Error 200: 
[ERROR    2014-09-01 12:26:38,692 bulkloader.py] Authentication Failed: Incorrect credentials or unsupported authentication type (e.g. OpenId).
